Workbook

Sheet 2024 MOM Station Sale
A1: RETAIL SALES SUMMARY ANALYSIS REPORT -
A2: TOTAL VOLUME (LTRS) AS @
A3: S/N | B3: Area | C3: Station | D3: Total Sales (Ltrs) Jan 2024 | I3: Total Sales (Ltrs) Feb 2024 | N3: Total Sales (Ltrs) Mar 2024 | S3: Total Sales (Ltrs) Apr 2024 | X3: Total Sales (Ltrs) May 2024 | AC3: Total Sales (Ltrs) Jun 2024 | AH3: Total Sales (Ltrs) Jul 2024 | AM3: Total Sales (Ltrs) Aug 2024 | AR3: Total Sales (Ltrs) Sept 2024 | AW3: Total Sales (Ltrs) Oct 2024 | BB3: Total Sales (Ltrs) Nov 2024 | BG3: Total Sales (Ltrs) Dec 2024
D4: PMS | E4: AGO | F4: DPK | G4: AVG PMS PRICE | H4: AVG AGO PRICE | I4: PMS | J4: AGO | K4: DPK | L4: AVG PMS PRICE | M4: AVG AGO PRICE | N4: PMS | O4: AGO | P4: DPK | Q4: AVG PMS PRICE | R4: AVG AGO PRICE | S4: PMS | T4: AGO | U4: DPK | V4: AVG PMS PRICE | W4: AVG AGO PRICE | X4: PMS | Y4: AGO | Z4: DPK | AA4: AVG PMS PRICE | AB4: AVG AGO PRICE | AC4: PMS | AD4: AGO | AE4: DPK | AF4: AVG PMS PRICE | AG4: AVG AGO PRICE | AH4: PMS | AI4: AGO | AJ4: DPK | AK4: AVG PMS PRICE | AL4: AVG AGO PRICE | AM4: PMS | AN4: AGO | AO4: DPK | AP4: AVG PMS PRICE | AQ4: AVG AGO PRICE | AR4: PMS | AS4: AGO | AT4: DPK | AU4: AVG PMS PRICE | AV4: AVG AGO PRICE | AW4: PMS | AX4: AGO | AY4: DPK | AZ4: AVG PMS PRICE | BA4: AVG AGO PRICE | BB4: PMS | BC4: AGO | BD4: DPK | BE4: AVG PMS PRICE | BF4: AVG AGO PRICE | BG4: PMS | BH4: AGO | BI4: DPK | BJ4: AVG PMS PRICE | BK4: AVG AGO PRICE
A5: 1 | B5: Calabar-PH | C5: Uyo - Abak Road | D5: 270296 | E5: 11485 | F5: 475 | G5: 666.45161 | H5: 1091.6129 | I5: 234352 | J5: 11483 | K5: 0 | L5: 678.21429 | M5: 1380.3571 | N5: 239839 | O5: 19172 | P5: 0 | Q5: 695 | R5: 1607.2581 | S5: 225443 | T5: 18164 | U5: 456 | V5: 697.83333 | W5: 1468.3333 | X5: 276542 | Y5: 25159 | Z5: 4545 | AA5: 806.45161 | AB5: 1253.5484 | AC5: 234508 | AD5: 33408 | AE5: 2021 | AF5: 754.33333 | AG5: 1241.3333 | AH5: 323863 | AI5: 10147 | AJ5: 3122 | AK5: 762.58065 | AL5: 1260 | AM5: 348052 | AN5: 12780 | AO5: 2731 | AP5: 849.67742 | AQ5: 1260 | AR5: 141602 | AS5: 9107 | AT5: 3307 | AU5: 1096 | AV5: 1260 | AW5: 161719 | AX5: 13480 | AY5: 4771 | AZ5: 1192.2581 | BA5: 1246.4516 | BB5: 174819 | BC5: 21325 | BD5: 3862 | BE5: 1131.1667 | BF5: 1200 | BG5: 217268 | BH5: 24490 | BI5: 3820 | BJ5: 1072.5806 | BK5: 1200
A6: 2 | B6: South-East 2 | C6: Abakaliki - Azuiyiokwu | D6: 152539 | E6: 4009 | F6: 360 | G6: 659.35484 | H6: 1080.8065 | I6: 138310 | J6: 4994 | K6: 376 | L6: 680.35714 | M6: 1387.1429 | N6: 143129 | O6: 4523 | P6: 1008 | Q6: 695 | R6: 1620.9677 | S6: 190219 | T6: 4130 | U6: 1758 | V6: 700.5 | W6: 1440 | X6: 184337 | Y6: 1451 | Z6: 416 | AA6: 799.67742 | AB6: 1254.5161 | AC6: 134764 | AD6: 2387 | AE6: 137 | AF6: 756.33333 | AG6: 1216.3333 | AH6: 160630 | AI6: 2179 | AJ6: 745 | AK6: 770.32258 | AL6: 1220 | AM6: 124381 | AN6: 6935 | AO6: 2723 | AP6: 871.29032 | AQ6: 1220 | AR6: 119289 | AS6: 5324 | AT6: 909 | AU6: 1186.6667 | AV6: 1220 | AW6: 168312 | AX6: 7430 | AY6: 1492 | AZ6: 1219.3548 | BA6: 1220 | BB6: 153093 | BC6: 9024 | BD6: 403 | BE6: 1152.3333 | BF6: 1201.6667 | BG6: 128274 | BH6: 10117 | BI6: 429 | BJ6: 1086.4516 | BK6: 1170
A7: 3 | B7: South-East 2 | C7: Abakaliki - Mile 50 | D7: 233337 | E7: 11807 | F7: 251 | G7: 666.77419 | H7: 1080.8065 | I7: 247296 | J7: 11367 | K7: 359 | L7: 687.85714 | M7: 1408.5714 | N7: 286621 | O7: 15551 | P7: 533 | Q7: 695 | R7: 1604.8387 | S7: 303667 | T7: 13280 | U7: 712 | V7: 700.5 | W7: 1440 | X7: 143846 | Y7: 7433 | Z7: 110 | AA7: 799.67742 | AB7: 1254.5161 | AC7: 239122 | AD7: 12700 | AE7: 0 | AF7: 756.33333 | AG7: 1216.3333 | AH7: 242895 | AI7: 10912 | AJ7: 159 | AK7: 770.32258 | AL7: 1220 | AM7: 95050 | AN7: 5467 | AO7: 0 | AP7: 871.29032 | AQ7: 1220 | AR7: 122190 | AS7: 5032 | AT7: 0 | AU7: 1186.6667 | AV7: 1220 | AW7: 249419 | AX7: 8550 | AY7: 119 | AZ7: 1219.3548 | BA7: 1220 | BB7: 247434 | BC7: 10826 | BD7: 256 | BE7: 1152.3333 | BF7: 1201.6667 | BG7: 244516 | BH7: 13490 | BI7: 325 | BJ7: 1086.4516 | BK7: 1170
A8: 4 | B8: South-East 2 | C8: Aba - Abayi-Osisioma | D8: 247810 | E8: 16374 | F8: 546 | G8: 672.58065 | H8: 1080.4839 | I8: 265581 | J8: 12448 | K8: 1880 | L8: 688.57143 | M8: 1392.5 | N8: 315660 | O8: 15303 | P8: 416 | Q8: 695 | R8: 1604.8387 | S8: 320551 | T8: 14290 | U8: 947 | V8: 700.53333 | W8: 1440 | X8: 185741 | Y8: 18540 | Z8: 567 | AA8: 800.96774 | AB8: 1264.1935 | AC8: 216793 | AD8: 13545 | AE8: 507 | AF8: 762.33333 | AG8: 1250.6667 | AH8: 284565 | AI8: 14189 | AJ8: 415 | AK8: 780.64516 | AL8: 1240 | AM8: 132048 | AN8: 8861 | AO8: 291 | AP8: 898.06452 | AQ8: 1240 | AR8: 141522 | AS8: 15680 | AT8: 280 | AU8: 1171.3333 | AV8: 1238.3333 | AW8: 160751 | AX8: 11384 | AY8: 378 | AZ8: 1217.7419 | BA8: 1220 | BB8: 150701 | BC8: 17316 | BD8: 358 | BE8: 1134.1667 | BF8: 1203 | BG8: 161975 | BH8: 11660 | BI8: 357 | BJ8: 1085.1613 | BK8: 1190.0645
A9: 5 | B9: South-West 1 | C9: Abijo | D9: 288364 | E9: 68637 | F9: 1543 | G9: 608.87097 | H9: 1022.5806 | I9: 385050 | J9: 83634 | K9: 1464 | L9: 632.14286 | M9: 1384.2857 | N9: 399108 | O9: 62832 | P9: 2042 | Q9: 634.67742 | R9: 1533.871 | S9: 696738 | T9: 89417 | U9: 1284 | V9: 643.16667 | W9: 1403.3333 | X9: 417511 | Y9: 65273 | Z9: 1296 | AA9: 681.6129 | AB9: 1224.1935 | AC9: 418297 | AD9: 45606 | AE9: 1521 | AF9: 625.83333 | AG9: 1201.3333 | AH9: 444532 | AI9: 53165 | AJ9: 1423 | AK9: 707.41935 | AL9: 1220 | AM9: 367278 | AN9: 42638 | AO9: 946 | AP9: 791.29032 | AQ9: 1220 | AR9: 376716 | AS9: 43336 | AT9: 667 | AU9: 955.33333 | AV9: 1220 | AW9: 383380 | AX9: 35100 | AY9: 955 | AZ9: 1075.4839 | BA9: 1214.1935 | BB9: 263481 | BC9: 53875 | BD9: 932 | BE9: 1091.3333 | BF9: 1185 | BG9: 209056 | BH9: 43820 | BI9: 947 | BJ9: 1066.129 | BK9: 1160.9677
A10: 6 | B10: Agbor | C10: Abraka | D10: 253426 | E10: 25373 | F10: 0 | G10: 652.25806 | H10: 1057.9032 | I10: 287365 | J10: 16394 | K10: 0 | L10: 669.46429 | M10: 1407.1429 | N10: 290054 | O10: 16456 | P10: 0 | Q10: 695 | R10: 1590.3226 | S10: 311000 | T10: 34368 | U10: 0 | V10: 695 | W10: 1345.3333 | X10: 396845 | Y10: 23534 | Z10: 0 | AA10: 750.32258 | AB10: 1194.8387 | AC10: 271804 | AD10: 22738 | AE10: 0 | AF10: 741.33333 | AG10: 1192.3333 | AH10: 320247 | AI10: 25281 | AJ10: 0 | AK10: 760.48387 | AL10: 1190 | AM10: 205046 | AN10: 18125 | AO10: 0 | AP10: 867.09677 | AQ10: 1190.9677 | AR10: 259316 | AS10: 21680 | AT10: 0 | AU10: 1117.5 | AV10: 1190 | AW10: 219119 | AX10: 18518 | AY10: 0 | AZ10: 1162.2581 | BA10: 1194.8387 | BB10: 224318 | BC10: 21273 | BD10: 0 | BE10: 1132.6667 | BF10: 1179.3333 | BG10: 215180 | BH10: 16326 | BI10: 0 | BJ10: 1084.8387 | BK10: 1153.2258
A11: 7 | B11: FCT | C11: FCT - Gwarimpa | D11: 549970 | E11: 40634 | F11: 0 | G11: 660 | H11: 1075.4839 | I11: 628075 | J11: 54351 | K11: 0 | L11: 672.85714 | M11: 1397.8571 | N11: 675603 | O11: 68200 | P11: 0 | Q11: 680 | R11: 1594.3548 | S11: 740906 | T11: 68907 | U11: 0 | V11: 683.33333 | W11: 1389 | X11: 754478 | Y11: 48566 | Z11: 0 | AA11: 692.09677 | AB11: 1234.0323 | AC11: 680504 | AD11: 51321 | AE11: 0 | AF11: 680.66667 | AG11: 1210.3333 | AH11: 833076 | AI11: 35761 | AJ11: 0 | AK11: 695.09677 | AL11: 1220 | AM11: 565017 | AN11: 30369 | AO11: 0 | AP11: 703.74194 | AQ11: 1220 | AR11: 537929 | AS11: 31367 | AT11: 0 | AU11: 979.66667 | AV11: 1220 | AW11: 652495 | AX11: 40325 | AY11: 0 | AZ11: 1090.6452 | BA11: 1220 | BB11: 407718 | BC11: 36642 | BD11: 0 | BE11: 1131.1667 | BF11: 1195 | BG11: 361070 | BH11: 26998 | BI11: 0 | BJ11: 1085.4839 | BK11: 1190
A12: 8 | B12: FCT | C12: FCT - Karmo | D12: 296019 | E12: 13335 | F12: 0 | G12: 660 | H12: 1075.4839 | I12: 318121 | J12: 20227 | K12: 0 | L12: 672.85714 | M12: 1401.6071 | N12: 397032 | O12: 28022 | P12: 0 | Q12: 680 | R12: 1594.3548 | S12: 402344 | T12: 19251 | U12: 0 | V12: 683.33333 | W12: 1389 | X12: 495324 | Y12: 21339 | Z12: 0 | AA12: 692.09677 | AB12: 1232.0968 | AC12: 351197 | AD12: 22584 | AE12: 0 | AF12: 683.66667 | AG12: 1210.3333 | AH12: 431477 | AI12: 38290 | AJ12: 0 | AK12: 695.09677 | AL12: 1220 | AM12: 185441 | AN12: 10409 | AO12: 0 | AP12: 703.74194 | AQ12: 1220 | AR12: 210166 | AS12: 22056 | AT12: 0 | AU12: 981 | AV12: 1220 | AW12: 420414 | AX12: 15815 | AY12: 0 | AZ12: 1090.6452 | BA12: 1220 | BB12: 320518 | BC12: 17409 | BD12: 0 | BE12: 1131.8333 | BF12: 1195 | BG12: 258921 | BH12: 8704 | BI12: 0 | BJ12: 1086.7742 | BK12: 1190
A13: 9 | B13: South-West 2 | C13: Ado-Ekiti - Ikere Road | D13: 158064 | E13: 4163 | F13: 0 | G13: 625 | H13: 1057.7419 | I13: 127613 | J13: 8577 | K13: 0 | L13: 644.64286 | M13: 1393.75 | N13: 110502 | O13: 4834 | P13: 0 | Q13: 663.87097 | R13: 1562.9032 | S13: 170677 | T13: 6509 | U13: 0 | V13: 663.33333 | W13: 1393.3333 | X13: 76069 | Y13: 5194 | Z13: 0 | AA13: 746.12903 | AB13: 1228.3871 | AC13: 79413 | AD13: 2960 | AE13: 0 | AF13: 670.66667 | AG13: 1219.3333 | AH13: 232003 | AI13: 5424 | AJ13: 0 | AK13: 734.19355 | AL13: 1200 | AM13: 102345 | AN13: 2610 | AO13: 0 | AP13: 818.06452 | AQ13: 1200 | AR13: 151975 | AS13: 3020 | AT13: 0 | AU13: 998.66667 | AV13: 1200 | AW13: 148017 | AX13: 2737 | AY13: 0 | AZ13: 1088.3871 | BA13: 1200 | BB13: 79399 | BC13: 3026 | BD13: 0 | BE13: 1090.6667 | BF13: 1178.3333 | BG13: 72558 | BH13: 4096 | BI13: 0 | BJ13: 1044.5161 | BK13: 1150
A14: 10 | B14: Warri | C14: Agbarho - Ohrerhe | D14: 282728 | E14: 7871 | F14: 362 | G14: 650.48387 | H14: 1053.7097 | I14: 275307 | J14: 14417 | K14: 274 | L14: 668.75 | M14: 1372.5 | N14: 248905 | O14: 14158 | P14: 83 | Q14: 695 | R14: 1590.3226 | S14: 262811 | T14: 48969 | U14: 0 | V14: 695 | W14: 1353.6667 | X14: 264549 | Y14: 18683 | Z14: 0 | AA14: 742.58065 | AB14: 1194.8387 | AC14: 227898 | AD14: 10069 | AE14: 0 | AF14: 721 | AG14: 1201.3333 | AH14: 252946 | AI14: 6289 | AJ14: 0 | AK14: 749.51613 | AL14: 1220 | AM14: 168446 | AN14: 5746 | AO14: 0 | AP14: 850 | AQ14: 1220 | AR14: 201027 | AS14: 4536 | AT14: 0 | AU14: 1105.3333 | AV14: 1220 | AW14: 185205 | AX14: 4317 | AY14: 0 | AZ14: 1150.6452 | BA14: 1211.2903 | BB14: 138382 | BC14: 14035 | BD14: 0 | BE14: 1138.3333 | BF14: 1179.3333 | BG14: 142184 | BH14: 17068 | BI14: 0 | BJ14: 1073.871 | BK14: 1153.2258
A15: 11 | B15: Warri | C15: Agbarho - Ewherhe | D15: 212457 | E15: 9281 | F15: 0 | G15: 650.48387 | H15: 1053.7097 | I15: 188130 | J15: 7997 | K15: 0 | L15: 668.75 | M15: 1385 | N15: 209388 | O15: 10045 | P15: 0 | Q15: 695 | R15: 1590.3226 | S15: 234918 | T15: 12715 | U15: 0 | V15: 695 | W15: 1353.6667 | X15: 232921 | Y15: 8912 | Z15: 0 | AA15: 742.58065 | AB15: 1197.4194 | AC15: 228757 | AD15: 8454 | AE15: 0 | AF15: 721.66667 | AG15: 1201.3333 | AH15: 259902 | AI15: 4944 | AJ15: 0 | AK15: 749.51613 | AL15: 1219.3548 | AM15: 133957 | AN15: 5289 | AO15: 0 | AP15: 850 | AQ15: 1220 | AR15: 182008 | AS15: 18001 | AT15: 0 | AU15: 1106.8333 | AV15: 1220 | AW15: 235130 | AX15: 6214 | AY15: 0 | AZ15: 1150.6452 | BA15: 1211.2903 | BB15: 219252 | BC15: 6748 | BD15: 0 | BE15: 1138.3333 | BF15: 1179.3333 | BG15: 208163 | BH15: 9841 | BI15: 0 | BJ15: 1081.6129 | BK15: 1153.2258
A16: 12 | B16: Agbor | C16: Agbor - Asaba Road | D16: 396944 | E16: 73915 | F16: 0 | G16: 656.29032 | H16: 1057.9032 | I16: 385575 | J16: 73622 | K16: 0 | L16: 670.17857 | M16: 1406.4286 | N16: 396199 | O16: 56825 | P16: 8 | Q16: 695 | R16: 1590.3226 | S16: 376272 | T16: 82028 | U16: 7 | V16: 693.5 | W16: 1353.6667 | X16: 387872 | Y16: 81793 | Z16: 0 | AA16: 741.6129 | AB16: 1197.4194 | AC16: 309969 | AD16: 80931 | AE16: 0 | AF16: 732.33333 | AG16: 1182.3333 | AH16: 375359 | AI16: 69998 | AJ16: 0 | AK16: 761.77419 | AL16: 1190 | AM16: 280321 | AN16: 68473 | AO16: 0 | AP16: 867.09677 | AQ16: 1190 | AR16: 247611 | AS16: 68853 | AT16: 0 | AU16: 1117.5 | AV16: 1190 | AW16: 276939 | AX16: 45772 | AY16: 0 | AZ16: 1161.6129 | BA16: 1194.8387 | BB16: 280986 | BC16: 52022 | BD16: 252 | BE16: 1132.6667 | BF16: 1179.3333 | BG16: 280570 | BH16: 53484 | BI16: 615 | BJ16: 1088.0645 | BK16: 1153.2258
... A172: 168 | B172: Ozoro | C172: Eku Town | D172: 176255 | E172: 12049 | F172: 0 | G172: 652.25806 | H172: 1057.7419 | I172: 157557 | J172: 25857 | K172: 0 | L172: 669.46429 | M172: 1406.4286 | N172: 198071 | O172: 37289 | P172: 0 | Q172: 695 | R172: 1590.3226 | S172: 206872 | T172: 58368 | U172: 0 | V172: 695 | W172: 1340.3333 | X172: 289195 | Y172: 56439 | Z172: 0 | AA172: 747.41935 | AB172: 1197.4194 | AC172: 224615 | AD172: 56641 | AE172: 0 | AF172: 738.33333 | AG172: 1188.3333 | AH172: 274541 | AI172: 50248 | AJ172: 0 | AK172: 760.48387 | AL172: 1190 | AM172: 198200 | AN172: 23382 | AO172: 0 | AP172: 867.09677 | AQ172: 1190.9677 | AR172: 269743 | AS172: 31506 | AT172: 0 | AU172: 1117.5 | AV172: 1190 | AW172: 214436 | AX172: 32016 | AY172: 0 | AZ172: 1162.2581 | BA172: 1194.8387 | BB172: 221436 | BC172: 38081 | BD172: 0 | BE172: 1132.3333 | BF172: 1179.3333 | BG172: 208730 | BH172: 28847 | BI172: 0 | BJ172: 1087.4194 | BK172: 1153.2258
A173: 169 | B173: North East | C173: Maiduguri | D173: 0 | E173: 0 | F173: 0 | G173: #DIV/0! | H173: #DIV/0! | I173: 163237 | J173: 30624 | K173: 0 | L173: 687.75 | M173: 1434.5 | N173: 262102 | O173: 15870 | P173: 0 | Q173: 703.22581 | R173: 1606.129 | S173: 186995 | T173: 6536 | U173: 0 | V173: 722.16667 | W173: 1476 | X173: 262467 | Y173: 10114 | Z173: 0 | AA173: 822.90323 | AB173: 1256.7742 | AC173: 244649 | AD173: 9856 | AE173: 0 | AF173: 740.66667 | AG173: 1210.3333 | AH173: 247259 | AI173: 9388 | AJ173: 0 | AK173: 808.70968 | AL173: 1230 | AM173: 162540 | AN173: 4147 | AO173: 0 | AP173: 880.64516 | AQ173: 1231.6129 | AR173: 87927 | AS173: 3404 | AT173: 0 | AU173: 1118.6667 | AV173: 1230 | AW173: 133641 | AX173: 9331 | AY173: 0 | AZ173: 1199.0323 | BA173: 1219.3548 | BB173: 139072 | BC173: 9816 | BD173: 0 | BE173: 1156.3333 | BF173: 1200.6667 | BG173: 110068 | BH173: 5020 | BI173: 0 | BJ173: 1110.3226 | BK173: 1200
A174: 170 | B174: Agbor | C174: Agbor - Alihamie | D174: 0 | E174: 0 | F174: 0 | G174: #DIV/0! | H174: #DIV/0! | I174: 0 | J174: 0 | K174: 0 | L174: #DIV/0! | M174: #DIV/0! | N174: 0 | O174: 0 | P174: 0 | Q174: #DIV/0! | R174: #DIV/0! | S174: 248365 | T174: 9621 | U174: 0 | V174: 695 | W174: 1337.4074 | X174: 311957 | Y174: 11532 | Z174: 0 | AA174: 741.6129 | AB174: 1197.4194 | AC174: 287548 | AD174: 9467 | AE174: 0 | AF174: 732.33333 | AG174: 1182.3333 | AH174: 269835 | AI174: 8661 | AJ174: 0 | AK174: 761.77419 | AL174: 1190 | AM174: 136223 | AN174: 6605 | AO174: 0 | AP174: 867.09677 | AQ174: 1190 | AR174: 206481 | AS174: 12059 | AT174: 0 | AU174: 1117.5 | AV174: 1190 | AW174: 248188 | AX174: 12844 | AY174: 0 | AZ174: 1161.6129 | BA174: 1194.8387 | BB174: 244913 | BC174: 12303 | BD174: 0 | BE174: 1132.6667 | BF174: 1179.3333 | BG174: 249709 | BH174: 23562 | BI174: 0 | BJ174: 1087.4194 | BK174: 1153.2258
A175: 171 | B175: Warri | C175: Orerokpo | D175: 0 | E175: 0 | F175: 0 | G175: #DIV/0! | H175: #DIV/0! | I175: 0 | J175: 0 | K175: 0 | L175: #DIV/0! | M175: #DIV/0! | N175: 0 | O175: 0 | P175: 0 | Q175: #DIV/0! | R175: #DIV/0! | S175: 98989 | T175: 5878 | U175: 0 | V175: 681.42857 | W175: 1287.1429 | X175: 209085 | Y175: 14502 | Z175: 0 | AA175: 729.67742 | AB175: 1194.8387 | AC175: 198790 | AD175: 15439 | AE175: 0 | AF175: 736.33333 | AG175: 1201.3333 | AH175: 225139 | AI175: 15210 | AJ175: 0 | AK175: 749.19355 | AL175: 1220 | AM175: 115578 | AN175: 13032 | AO175: 0 | AP175: 867.41935 | AQ175: 1220 | AR175: 162320 | AS175: 12975 | AT175: 0 | AU175: 1108.8333 | AV175: 1220 | AW175: 213646 | AX175: 37765 | AY175: 0 | AZ175: 1150.6452 | BA175: 1211.2903 | BB175: 210507 | BC175: 32678 | BD175: 0 | BE175: 1138.3333 | BF175: 1179.3333 | BG175: 230570 | BH175: 22017 | BI175: 0 | BJ175: 1081.6129 | BK175: 1153.2258
A176: 172 | B176: Calabar-PH | C176: Uyo Idoro Road | D176: 0 | E176: 0 | F176: 0 | G176: #DIV/0! | H176: #DIV/0! | I176: 0 | J176: 0 | K176: 0 | L176: #DIV/0! | M176: #DIV/0! | N176: 0 | O176: 0 | P176: 0 | Q176: #DIV/0! | R176: #DIV/0! | S176: 0 | T176: 0 | U176: 0 | V176: #DIV/0! | W176: #DIV/0! | X176: 0 | Y176: 0 | Z176: 0 | AA176: #DIV/0! | AB176: #DIV/0! | AC176: 48793 | AD176: 5987 | AE176: 0 | AF176: 723.33333 | AG176: 1200 | AH176: 414471 | AI176: 31997 | AJ176: 0 | AK176: 762.58065 | AL176: 1200 | AM176: 491606 | AN176: 49259 | AO176: 0 | AP176: 849.67742 | AQ176: 1200 | AR176: 181828 | AS176: 54742 | AT176: 0 | AU176: 1114 | AV176: 1222 | AW176: 234681 | AX176: 56316 | AY176: 0 | AZ176: 1190.3226 | BA176: 1245.8065 | BB176: 301090 | BC176: 78899 | BD176: 0 | BE176: 1130.5 | BF176: 1200 | BG176: 374864 | BH176: 82811 | BI176: 0 | BJ176: 1069.3548 | BK176: 1200
A177: 173 | B177: South-West 1 | C177: Sagamu | D177: 0 | E177: 0 | F177: 0 | G177: #DIV/0! | H177: #DIV/0! | I177: 0 | J177: 0 | K177: 0 | L177: #DIV/0! | M177: #DIV/0! | N177: 0 | O177: 0 | P177: 0 | Q177: #DIV/0! | R177: #DIV/0! | S177: 0 | T177: 0 | U177: 0 | V177: #DIV/0! | W177: #DIV/0! | X177: 0 | Y177: 0 | Z177: 0 | AA177: #DIV/0! | AB177: #DIV/0! | AC177: 0 | AD177: 0 | AE177: 0 | AF177: #DIV/0! | AG177: #DIV/0! | AH177: 432494 | AI177: 3109 | AJ177: 0 | AK177: 713.91304 | AL177: 1220 | AM177: 361217 | AN177: 1319 | AO177: 0 | AP177: 791.29032 | AQ177: 1220 | AR177: 477772 | AS177: 2514 | AT177: 0 | AU177: 956.66667 | AV177: 1220 | AW177: 487759 | AX177: 4096 | AY177: 0 | AZ177: 1075.4839 | BA177: 1214.1935 | BB177: 235851 | BC177: 8257 | BD177: 0 | BE177: 1091.3333 | BF177: 1185 | BG177: 218192 | BH177: 9665 | BI177: 0 | BJ177: 1059.0323 | BK177: 1160.9677
A178: 174 | B178: Yenagoa | C178: Yenagoa Opolo-Epie | D178: 0 | E178: 0 | F178: 0 | G178: #DIV/0! | H178: #DIV/0! | I178: 0 | J178: 0 | K178: 0 | L178: #DIV/0! | M178: #DIV/0! | N178: 0 | O178: 0 | P178: 0 | Q178: #DIV/0! | R178: #DIV/0! | S178: 0 | T178: 0 | U178: 0 | V178: #DIV/0! | W178: #DIV/0! | X178: 0 | Y178: 0 | Z178: 0 | AA178: #DIV/0! | AB178: #DIV/0! | AC178: 0 | AD178: 0 | AE178: 0 | AF178: #DIV/0! | AG178: #DIV/0! | AH178: 177889 | AI178: 1487 | AJ178: 0 | AK178: 853.33333 | AL178: 1255 | AM178: 208286 | AN178: 1578 | AO178: 0 | AP178: 901.6129 | AQ178: 1255 | AR178: 221941 | AS178: 395 | AT178: 0 | AU178: 1074.3333 | AV178: 1255 | AW178: 227635 | AX178: 12794 | AY178: 0 | AZ178: 1232.2581 | BA178: 1244.8387 | BB178: 303561 | BC178: 8469 | BD178: 0 | BE178: 1141.3333 | BF178: 1215.3333 | BG178: 242357 | BH178: 11293 | BI178: 0 | BJ178: 1086.7742 | BK178: 1200
A179: 175 | B179: South East 1 | C179: Nnewi - Otolo | D179: 0 | E179: 0 | F179: 0 | G179: #DIV/0! | H179: #DIV/0! | I179: 0 | J179: 0 | K179: 0 | L179: #DIV/0! | M179: #DIV/0! | N179: 0 | O179: 0 | P179: 0 | Q179: #DIV/0! | R179: #DIV/0! | S179: 0 | T179: 0 | U179: 0 | V179: #DIV/0! | W179: #DIV/0! | X179: 0 | Y179: 0 | Z179: 0 | AA179: #DIV/0! | AB179: #DIV/0! | AC179: 0 | AD179: 0 | AE179: 0 | AF179: #DIV/0! | AG179: #DIV/0! | AH179: 0 | AI179: 0 | AJ179: 0 | AK179: #DIV/0! | AL179: #DIV/0! | AM179: 0 | AN179: 0 | AO179: 0 | AP179: #DIV/0! | AQ179: #DIV/0! | AR179: 0 | AS179: 0 | AT179: 0 | AU179: #DIV/0! | AV179: #DIV/0! | AW179: 36547 | AX179: 4476 | AY179: 0 | AZ179: 1200 | BA179: 1220 | BB179: 194412 | BC179: 34075 | BD179: 0 | BE179: 1157.3333 | BF179: 1212.6667 | BG179: 224109 | BH179: 35080 | BI179: 0 | BJ179: 1100.3226 | BK179: 1200.6452
A180: 176 | B180: Kwale | C180: Okpanam - City Gate | D180: 0 | E180: 0 | F180: 0 | G180: #DIV/0! | H180: #DIV/0! | I180: 0 | J180: 0 | K180: 0 | L180: #DIV/0! | M180: #DIV/0! | N180: 0 | O180: 0 | P180: 0 | Q180: #DIV/0! | R180: #DIV/0! | S180: 0 | T180: 0 | U180: 0 | V180: #DIV/0! | W180: #DIV/0! | X180: 0 | Y180: 0 | Z180: 0 | AA180: #DIV/0! | AB180: #DIV/0! | AC180: 0 | AD180: 0 | AE180: 0 | AF180: #DIV/0! | AG180: #DIV/0! | AH180: 0 | AI180: 0 | AJ180: 0 | AK180: #DIV/0! | AL180: #DIV/0! | AM180: 0 | AN180: 0 | AO180: 0 | AP180: #DIV/0! | AQ180: #DIV/0! | AR180: 0 | AS180: 0 | AT180: 0 | AU180: #DIV/0! | AV180: #DIV/0! | AW180: 0 | AX180: 0 | AY180: 0 | AZ180: #DIV/0! | BA180: #DIV/0! | BB180: 109547 | BC180: 9610 | BD180: 0 | BE180: 1129.3103 | BF180: 1178.9655 | BG180: 140062 | BH180: 11096 | BI180: 0 | BJ180: 1086.129 | BK180: 1153.2258
A181: 177 | B181: Edo North | C181: Irrua - Teaching Hospital | D181: 0 | E181: 0 | F181: 0 | G181: #DIV/0! | H181: #DIV/0! | I181: 0 | J181: 0 | K181: 0 | L181: #DIV/0! | M181: #DIV/0! | N181: 0 | O181: 0 | P181: 0 | Q181: #DIV/0! | R181: #DIV/0! | S181: 0 | T181: 0 | U181: 0 | V181: #DIV/0! | W181: #DIV/0! | X181: 0 | Y181: 0 | Z181: 0 | AA181: #DIV/0! | AB181: #DIV/0! | AC181: 0 | AD181: 0 | AE181: 0 | AF181: #DIV/0! | AG181: #DIV/0! | AH181: 0 | AI181: 0 | AJ181: 0 | AK181: #DIV/0! | AL181: #DIV/0! | AM181: 0 | AN181: 0 | AO181: 0 | AP181: #DIV/0! | AQ181: #DIV/0! | AR181: 0 | AS181: 0 | AT181: 0 | AU181: #DIV/0! | AV181: #DIV/0! | AW181: 0 | AX181: 0 | AY181: 0 | AZ181: #DIV/0! | BA181: #DIV/0! | BB181: 12131 | BC181: 1177 | BD181: 0 | BE181: 1102 | BF181: 1150 | BG181: 104443 | BH181: 18303 | BI181: 0 | BJ181: 1084.5161 | BK181: 1150
A182: 178 | B182: Warri | C182: Udu - Udu Bridge Layout | D182: 0 | E182: 0 | F182: 0 | G182: #DIV/0! | H182: #DIV/0! | I182: 0 | J182: 0 | K182: 0 | L182: #DIV/0! | M182: #DIV/0! | N182: 0 | O182: 0 | P182: 0 | Q182: #DIV/0! | R182: #DIV/0! | S182: 0 | T182: 0 | U182: 0 | V182: #DIV/0! | W182: #DIV/0! | X182: 0 | Y182: 0 | Z182: 0 | AA182: #DIV/0! | AB182: #DIV/0! | AC182: 0 | AD182: 0 | AE182: 0 | AF182: #DIV/0! | AG182: #DIV/0! | AH182: 0 | AI182: 0 | AJ182: 0 | AK182: #DIV/0! | AL182: #DIV/0! | AM182: 0 | AN182: 0 | AO182: 0 | AP182: #DIV/0! | AQ182: #DIV/0! | AR182: 0 | AS182: 0 | AT182: 0 | AU182: #DIV/0! | AV182: #DIV/0! | AW182: 0 | AX182: 0 | AY182: 0 | AZ182: #DIV/0! | BA182: #DIV/0! | BB182: 6402 | BC182: 103 | BD182: 0 | BE182: 1120 | BF182: 1170 | BG182: 124383 | BH182: 4154 | BI182: 0 | BJ182: 1074.8387 | BK182: 1153.2258
A183: 179 | B183: Agbor | C183: Umunede | D183: 0 | E183: 0 | F183: 0 | G183: #DIV/0! | H183: #DIV/0! | I183: 0 | J183: 0 | K183: 0 | L183: #DIV/0! | M183: #DIV/0! | N183: 0 | O183: 0 | P183: 0 | Q183: #DIV/0! | R183: #DIV/0! | S183: 0 | T183: 0 | U183: 0 | V183: #DIV/0! | W183: #DIV/0! | X183: 0 | Y183: 0 | Z183: 0 | AA183: #DIV/0! | AB183: #DIV/0! | AC183: 0 | AD183: 0 | AE183: 0 | AF183: #DIV/0! | AG183: #DIV/0! | AH183: 0 | AI183: 0 | AJ183: 0 | AK183: #DIV/0! | AL183: #DIV/0! | AM183: 0 | AN183: 0 | AO183: 0 | AP183: #DIV/0! | AQ183: #DIV/0! | AR183: 0 | AS183: 0 | AT183: 0 | AU183: #DIV/0! | AV183: #DIV/0! | AW183: 0 | AX183: 0 | AY183: 0 | AZ183: #DIV/0! | BA183: #DIV/0! | BB183: 0 | BC183: 0 | BD183: 0 | BE183: #DIV/0! | BF183: #DIV/0! | BG183: 155665 | BH183: 11227 | BI183: 0 | BJ183: 1083.8462 | BK183: 1150

Sheet 2024 SUMMARY
A1: S/N | B1: MONTH | C1: PMS | D1: AGO | E1: DPK | F1: AVG PMS PRICE | G1: AVG AGO PRICE | H1: NO OF STATIONS
A2: 1 | B2: 45292 | C2: =SUM('2024 MOM Station Sale'!D5:D172) -> 44646728 | D2: =SUM('2024 MOM Station Sale'!E5:E172) -> 5662264 | E2: =SUM('2024 MOM Station Sale'!F5:F172) -> 103215 | F2: =AVERAGE('2024 MOM Station Sale'!G5:G172) -> 654.0457 | G2: =AVERAGE('2024 MOM Station Sale'!H5:H172) -> 1066.0536 | H2: =COUNTA('2024 MOM Station Sale'!C5:C172) -> 168
A3: =A2+1 -> 2 | B3: 45323 | C3: =SUM('2024 MOM Station Sale'!I5:I173) -> 45182760 | D3: =SUM('2024 MOM Station Sale'!J5:J173) -> 5641699 | E3: =SUM('2024 MOM Station Sale'!K5:K173) -> 119927 | F3: =AVERAGE('2024 MOM Station Sale'!L5:L173) -> 670.12299 | G3: =AVERAGE('2024 MOM Station Sale'!M5:M173) -> 1396.9474 | H3: =COUNTA('2024 MOM Station Sale'!C5:C173) -> 169
A4: =A3+1 -> 3 | B4: 45352 | C4: =SUM('2024 MOM Station Sale'!N5:N173) -> 45726064 | D4: =SUM('2024 MOM Station Sale'!O5:O173) -> 5392415 | E4: =SUM('2024 MOM Station Sale'!P5:P173) -> 124007 | F4: =AVERAGE('2024 MOM Station Sale'!Q5:Q173) -> 687.70605 | G4: =AVERAGE('2024 MOM Station Sale'!R5:R173) -> 1592.1015 | H4: =COUNTA('2024 MOM Station Sale'!C5:C173) -> 169
A5: =A4+1 -> 4 | B5: 45383 | C5: =SUM('2024 MOM Station Sale'!S5:S175) -> 50154114 | D5: =SUM('2024 MOM Station Sale'!T5:T175) -> 6069933 | E5: =SUM('2024 MOM Station Sale'!U5:U175) -> 103636 | F5: =AVERAGE('2024 MOM Station Sale'!V5:V175) -> 690.6795 | G5: =AVERAGE('2024 MOM Station Sale'!W5:W175) -> 1382.1358 | H5: =COUNTA('2024 MOM Station Sale'!E5:E175) -> 171
A6: =A5+1 -> 5 | B6: 45413 | C6: =SUM('2024 MOM Station Sale'!X5:X175) -> 45996285 | D6: =SUM('2024 MOM Station Sale'!Y5:Y175) -> 5735188 | E6: =SUM('2024 MOM Station Sale'!Z5:Z175) -> 140255 | F6: =AVERAGE('2024 MOM Station Sale'!AA5:AA175) -> 756.96057 | G6: =AVERAGE('2024 MOM Station Sale'!AB5:AB175) -> 1217.3467 | H6: =COUNTA('2024 MOM Station Sale'!AA5:AA175) -> 171
A7: =A6+1 -> 6 | B7: 45444 | C7: =SUM('2024 MOM Station Sale'!AC5:AC176) -> 42594588 | D7: =SUM('2024 MOM Station Sale'!AD5:AD176) -> 5141686 | E7: =SUM('2024 MOM Station Sale'!AE5:AE176) -> 97487 | F7: =AVERAGE('2024 MOM Station Sale'!AF5:AF176) -> 727.59302 | G7: =AVERAGE('2024 MOM Station Sale'!AG5:AG176) -> 1206.0678 | H7: =COUNTA('2024 MOM Station Sale'!AF5:AF176) -> 172
A8: =A7+1 -> 7 | B8: 45474 | C8: =SUM('2024 MOM Station Sale'!AH5:AH178) -> 52243943 | D8: =SUM('2024 MOM Station Sale'!AI5:AI178) -> 4489107 | E8: =SUM('2024 MOM Station Sale'!AJ5:AJ178) -> 111872 | F8: =AVERAGE('2024 MOM Station Sale'!AK5:AK178) -> 752.22296 | G8: =AVERAGE('2024 MOM Station Sale'!AL5:AL178) -> 1219.2733 | H8: =COUNTA('2024 MOM Station Sale'!AL5:AL178) -> 174
A9: =A8+1 -> 8 | B9: 45505 | C9: =SUM('2024 MOM Station Sale'!AM5:AM178) -> 33425135 | D9: =SUM('2024 MOM Station Sale'!AN5:AN178) -> 3434663 | E9: =SUM('2024 MOM Station Sale'!AO5:AO178) -> 93376 | F9: =AVERAGE('2024 MOM Station Sale'!AP5:AP178) -> 843.82833 | G9: =AVERAGE('2024 MOM Station Sale'!AQ5:AQ178) -> 1220.1659 | H9: =COUNTA('2024 MOM Station Sale'!AQ5:AQ178) -> 174
A10: =A9+1 -> 9 | B10: 45536 | C10: =SUM('2024 MOM Station Sale'!AR5:AR178) -> 37426911 | D10: =SUM('2024 MOM Station Sale'!AS5:AS178) -> 3907594 | E10: =SUM('2024 MOM Station Sale'!AT5:AT178) -> 84315 | F10: =AVERAGE('2024 MOM Station Sale'!AU5:AU178) -> 1089.477 | G10: =AVERAGE('2024 MOM Station Sale'!AV5:AV178) -> 1218.7289 | H10: =COUNTA('2024 MOM Station Sale'!AV5:AV178) -> 174
A11: =A10+1 -> 10 | B11: 45566 | C11: =SUM('2024 MOM Station Sale'!AW5:AW179) -> 41613504 | D11: =SUM('2024 MOM Station Sale'!AX5:AX179) -> 4741775 | E11: =SUM('2024 MOM Station Sale'!AY5:AY179) -> 118597 | F11: =AVERAGE('2024 MOM Station Sale'!AZ5:AZ179) -> 1165.2017 | G11: =AVERAGE('2024 MOM Station Sale'!BA5:BA179) -> 1214.471 | H11: =COUNTA('2024 MOM Station Sale'!AZ5:AZ179) -> 175
A12: =A11+1 -> 11 | B12: 45597 | C12: =SUM('2024 MOM Station Sale'!BB5:BB182) -> 37948798 | D12: =SUM('2024 MOM Station Sale'!BC5:BC182) -> 5698963 | E12: =SUM('2024 MOM Station Sale'!BD5:BD182) -> 87180 | F12: =AVERAGE('2024 MOM Station Sale'!BE5:BE182) -> 1133.9446 | G12: =AVERAGE('2024 MOM Station Sale'!BF5:BF182) -> 1189.2412 | H12: =COUNTA('2024 MOM Station Sale'!BF5:BF182) -> 178
A13: =A12+1 -> 12 | B13: 45627 | C13: =SUM('2024 MOM Station Sale'!BG5:BG183) -> 39144717 | D13: =SUM('2024 MOM Station Sale'!BH5:BH183) -> 5259672 | E13: =SUM('2024 MOM Station Sale'!BI5:BI183) -> 81387 | F13: =AVERAGE('2024 MOM Station Sale'!BJ5:BJ183) -> 1084.4511 | G13: =AVERAGE('2024 MOM Station Sale'!BK5:BK183) -> 1170.1283 | H13: =COUNTA('2024 MOM Station Sale'!BK5:BK183) -> 179

Sheet 2025 MOM Station Sale
A1: RETAIL SALES SUMMARY ANALYSIS REPORT -
A2: TOTAL VOLUME (LTRS) AS @ 2025
A3: S/N | B3: Area | C3: Station | D3: Total Sales (Ltrs) Jan 2025 | I3: Total Sales (Ltrs) Feb 2025 | N3: Total Sales (Ltrs) Mar 2025 | S3: Total Sales (Ltrs) Apr 2025 | X3: Total Sales (Ltrs) May 2025 | AC3: Total Sales (Ltrs) Jun 2025 | AH3: Total Sales (Ltrs) Jul 2025 | AM3: Total Sales (Ltrs) Aug 2025 | AR3: Total Sales (Ltrs) Sept 2025 | AW3: Total Sales (Ltrs) Oct 2025 | BB3: Total Sales (Ltrs) Nov 2025 | BG3: Total Sales (Ltrs) Dec 2025
D4: PMS | E4: AGO | F4: DPK | G4: AVG PMS PRICE | H4: AVG AGO PRICE | I4: PMS | J4: AGO | K4: DPK | L4: AVG PMS PRICE | M4: AVG AGO PRICE | N4: PMS | O4: ANO | P4: DPK | Q4: AVG PMS PRICE | R4: AVG AGO PRICE | S4: PMS | T4: ANO | U4: DPK | V4: AVG PMS PRICE | W4: AVG AGO PRICE | X4: PMS | Y4: ANO | Z4: DPK | AA4: AVG PMS PRICE | AB4: AVG AGO PRICE | AC4: PMS | AD4: ANO | AE4: DPK | AF4: AVG PMS PRICE | AG4: AVG AGO PRICE | AH4: PMS | AI4: ANO | AJ4: DPK | AK4: AVG PMS PRICE | AL4: AVG AGO PRICE | AM4: PMS | AN4: AGO | AO4: DPK | AP4: AVG PMS PRICE | AQ4: AVG AGO PRICE | AR4: PMS | AS4: AGO | AT4: DPK | AU4: AVG PMS PRICE | AV4: AVG AGO PRICE | AW4: PMS | AX4: AGO | AY4: DPK | AZ4: AVG PMS PRICE | BA4: AVG AGO PRICE | BB4: PMS | BC4: AGO | BD4: DPK | BE4: AVG PMS PRICE | BF4: AVG AGO PRICE | BG4: PMS | BH4: AGO | BI4: DPK | BJ4: AVG PMS PRICE | BK4: AVG AGO PRICE
A5: 1 | B5: Calabar-PH | C5: Rainoil Uyo - Abak Road | D5: 205727 | E5: 24315 | F5: 1478 | G5: 1013.5484 | H5: 1163.871 | I5: 172977 | J5: 16314 | K5: 0 | L5: 1001.0714 | M5: 1156.4286 | N5: 190999 | O5: 42951 | P5: 1186 | Q5: 942.58065 | R5: 1150 | S5: 193089 | T5: 14846 | U5: 1269 | V5: 944 | W5: 1145 | X5: 230659 | Y5: 20592 | Z5: 3249 | AA5: 909.35484 | AB5: 1092.5806 | AC5: 221380 | AD5: 12119 | AE5: 5498 | AF5: 920.5 | AG5: 1075.3333 | AH5: 206906 | AI5: 13298 | AJ5: 2139 | AK5: 918.70968 | AL5: 1093.2258 | AM5: 193333 | AN5: 15790 | AO5: 1388 | AP5: 910 | AQ5: 1107.0968 | AR5: 159743 | AS5: 13598 | AT5: 0 | AU5: 897 | AV5: 1090 | AW5: 170965 | AX5: 15593 | AY5: 0 | AZ5: 912.58065 | BA5: 1087.4194 | BB5: 178044 | BC5: 15444 | BD5: 0 | BE5: 920 | BF5: 1074 | BG5: 186963 | BH5: 17356 | BI5: 0 | BJ5: 892.25806 | BK5: 1050.9677
A6: 2 | B6: South-East 2 | C6: Rainoil Abakaliki - Azuiyiokwu | D6: 124314 | E6: 7586 | F6: 280 | G6: 1031.2903 | H6: 1170 | I6: 87898 | J6: 5687 | K6: 165 | L6: 1012.1429 | M6: 1170 | N6: 88175 | O6: 4165 | P6: 562 | Q6: 956.77419 | R6: 1159.0323 | S6: 79515 | T6: 6135 | U6: 93 | V6: 953.33333 | W6: 1145 | X6: 83096 | Y6: 5765 | Z6: 109 | AA6: 924.51613 | AB6: 1100 | AC6: 65979 | AD6: 6852 | AE6: 107 | AF6: 931.33333 | AG6: 1100.6667 | AH6: 84880 | AI6: 5422 | AJ6: 148 | AK6: 930.32258 | AL6: 1104.5161 | AM6: 74811 | AN6: 4948 | AO6: 138 | AP6: 913.22581 | AQ6: 1110.6452 | AR6: 78825 | AS6: 6937 | AT6: 193 | AU6: 881.33333 | AV6: 1090 | AW6: 82168 | AX6: 9441 | AY6: 112 | AZ6: 923.22581 | BA6: 1087.0968 | BB6: 64162 | BC6: 4861 | BD6: 520 | BE6: 940 | BF6: 1067.3333 | BG6: 96521 | BH6: 8629 | BI6: 520 | BJ6: 896.45161 | BK6: 1052.5806
A7: 3 | B7: South-East 2 | C7: Rainoil Abakaliki - Mile 50 | D7: 296645 | E7: 24598 | F7: 310 | G7: 1031.2903 | H7: 1170 | I7: 252950 | J7: 14833 | K7: 176 | L7: 1012.1429 | M7: 1170 | N7: 333730 | O7: 17464 | P7: 222 | Q7: 956.77419 | R7: 1159.0323 | S7: 317875 | T7: 21188 | U7: 297 | V7: 953.33333 | W7: 1145 | X7: 292914 | Y7: 21189 | Z7: 124 | AA7: 928.70968 | AB7: 1100 | AC7: 288334 | AD7: 24269 | AE7: 70 | AF7: 931.33333 | AG7: 1100.6667 | AH7: 325571 | AI7: 19462 | AJ7: 255 | AK7: 930.32258 | AL7: 1104.5161 | AM7: 320647 | AN7: 23579 | AO7: 327 | AP7: 913.22581 | AQ7: 1110.6452 | AR7: 284348 | AS7: 26476 | AT7: 368 | AU7: 881.33333 | AV7: 1090 | AW7: 323139 | AX7: 18719 | AY7: 400 | AZ7: 923.22581 | BA7: 1087.0968 | BB7: 298283 | BC7: 22116 | BD7: 328 | BE7: 940 | BF7: 1067.3333 | BG7: 345128 | BH7: 21452 | BI7: 381 | BJ7: 895.80645 | BK7: 1052.9032
A8: 4 | B8: South-East 2 | C8: Rainoil Aba - Abayi-Osisioma | D8: 135894 | E8: 11268 | F8: 520 | G8: 1032.9032 | H8: 1190 | I8: 91417 | J8: 7771 | K8: 211 | L8: 998.57143 | M8: 1186.7857 | N8: 76578 | O8: 14218 | P8: 296 | Q8: 950.64516 | R8: 1162.5806 | S8: 108355 | T8: 13446 | U8: 273 | V8: 948.33333 | W8: 1150 | X8: 106454 | Y8: 12545 | Z8: 21 | AA8: 919.67742 | AB8: 1130 | AC8: 95398 | AD8: 9573 | AE8: 141 | AF8: 921.33333 | AG8: 1100.6667 | AH8: 71621 | AI8: 9543 | AJ8: 328 | AK8: 926.45161 | AL8: 1104.5161 | AM8: 69452 | AN8: 7322 | AO8: 350 | AP8: 912.25806 | AQ8: 1111.2903 | AR8: 74144 | AS8: 8269 | AT8: 364 | AU8: 890.66667 | AV8: 1099.6667 | AW8: 81299 | AX8: 6574 | AY8: 307 | AZ8: 922.90323 | BA8: 1094.1935 | BB8: 81432 | BC8: 6029 | BD8: 262 | BE8: 930 | BF8: 1078.6667 | BG8: 132873 | BH8: 12290 | BI8: 378 | BJ8: 895.48387 | BK8: 1065.4839
A9: 5 | B9: South-West 1 | C9: Rainoil Abijo | D9: 255385 | E9: 70182 | F9: 850 | G9: 990 | H9: 1150.9677 | I9: 264753 | J9: 65713 | K9: 816 | L9: 972.39286 | M9: 1149.6429 | N9: 312854 | O9: 62739 | P9: 1178 | Q9: 899.67742 | R9: 1128.7097 | S9: 334379 | T9: 59716 | U9: 906 | V9: 918.83333 | W9: 1120 | X9: 346595 | Y9: 49682 | Z9: 1627 | AA9: 888.22581 | AB9: 1109.3548 | AC9: 310764 | AD9: 38527 | AE9: 1125 | AF9: 900.33333 | AG9: 1074 | AH9: 298739 | AI9: 42696 | AJ9: 1486 | AK9: 899.06452 | AL9: 1091.6129 | AM9: 276671 | AN9: 30827 | AO9: 1675 | AP9: 887.58065 | AQ9: 1095.1613 | AR9: 328467 | AS9: 42601 | AT9: 1433 | AU9: 870.66667 | AV9: 1050 | AW9: 359293 | AX9: 48545 | AY9: 1488 | AZ9: 903.3871 | BA9: 1047.7419 | BB9: 375475 | BC9: 50864 | BD9: 1359 | BE9: 921.26667 | BF9: 1039.3333 | BG9: 400927 | BH9: 45545 | BI9: 1358 | BJ9: 899.03226 | BK9: 1029.6774
A10: 6 | B10: Agbor | C10: Rainoil Abraka | D10: 182115 | E10: 19233 | F10: 0 | G10: 1008.871 | H10: 1150 | I10: 188525 | J10: 19649 | K10: 0 | L10: 998.75 | M10: 1144.2857 | N10: 203037 | O10: 20463 | P10: 0 | Q10: 938.87097 | R10: 1130 | S10: 197729 | T10: 13956 | U10: 0 | V10: 945.33333 | W10: 1111.6667 | X10: 200112 | Y10: 14543 | Z10: 0 | AA10: 913.22581 | AB10: 1072.9032 | AC10: 162139 | AD10: 15548 | AE10: 0 | AF10: 921.33333 | AG10: 1073 | AH10: 160352 | AI10: 19087 | AJ10: 0 | AK10: 922.25806 | AL10: 1082.2581 | AM10: 155624 | AN10: 16833 | AO10: 0 | AP10: 910.32258 | AQ10: 1107.4194 | AR10: 172777 | AS10: 18715 | AT10: 0 | AU10: 893.66667 | AV10: 1100 | AW10: 173051 | AX10: 18918 | AY10: 0 | AZ10: 915.16129 | BA10: 1088.0645 | BB10: 177378 | BC10: 16249 | BD10: 0 | BE10: 919.5 | BF10: 1062.6667 | BG10: 173091 | BH10: 16262 | BI10: 0 | BJ10: 900.48387 | BK10: 1039.6774
A11: 7 | B11: FCT | C11: Rainoil FCT - Gwarimpa | D11: 480413 | E11: 33941 | F11: 0 | G11: 1000 | H11: 1180.3226 | I11: 472614 | J11: 31142 | K11: 0 | L11: 989.28571 | M11: 1173.9286 | N11: 472924 | O11: 51852 | P11: 0 | Q11: 945.80645 | R11: 1170 | S11: 445730 | T11: 37117 | U11: 0 | V11: 950.66667 | W11: 1159 | X11: 401100 | Y11: 33007 | Z11: 0 | AA11: 920 | AB11: 1133.871 | AC11: 361691 | AD11: 23938 | AE11: 0 | AF11: 920.66667 | AG11: 1130 | AH11: 376009 | AI11: 22820 | AJ11: 0 | AK11: 917.58065 | AL11: 1106.7742 | AM11: 391195 | AN11: 24604 | AO11: 0 | AP11: 914.35484 | AQ11: 1123.2258 | AR11: 444478 | AS11: 35373 | AT11: 0 | AU11: 901.66667 | AV11: 1100 | AW11: 548707 | AX11: 34590 | AY11: 0 | AZ11: 935.80645 | BA11: 1087.7419 | BB11: 437770 | BC11: 28823 | BD11: 0 | BE11: 944.83333 | BF11: 1047.3333 | BG11: 383897 | BH11: 34226 | BI11: 0 | BJ11: 917.58065 | BK11: 1040
A12: 8 | B12: FCT | C12: Rainoil FCT - Karmo | D12: 256265 | E12: 11668 | F12: 0 | G12: 1000 | H12: 1180.3226 | I12: 255518 | J12: 14877 | K12: 0 | L12: 989.28571 | M12: 1173.9286 | N12: 322007 | O12: 13269 | P12: 0 | Q12: 945.80645 | R12: 1170 | S12: 316682 | T12: 12422 | U12: 0 | V12: 950.66667 | W12: 1159 | X12: 324385 | Y12: 16057 | Z12: 0 | AA12: 920 | AB12: 1133.871 | AC12: 277811 | AD12: 10649 | AE12: 0 | AF12: 920.66667 | AG12: 1130 | AH12: 262801 | AI12: 12073 | AJ12: 0 | AK12: 917.58065 | AL12: 1106.7742 | AM12: 269521 | AN12: 10583 | AO12: 0 | AP12: 914.03226 | AQ12: 1116.7742 | AR12: 239282 | AS12: 12857 | AT12: 0 | AU12: 896.66667 | AV12: 1100 | AW12: 372219 | AX12: 10873 | AY12: 0 | AZ12: 933.54839 | BA12: 1087.4194 | BB12: 261972 | BC12: 10458 | BD12: 0 | BE12: 943 | BF12: 1047.6667 | BG12: 228818 | BH12: 9320 | BI12: 0 | BJ12: 917.58065 | BK12: 1040
A13: 9 | B13: South-West 2 | C13: Rainoil Ado-Ekiti - Ikere Road | D13: 67297 | E13: 5392 | F13: 0 | G13: 990.96774 | H13: 1140.6452 | I13: 59390 | J13: 10018 | K13: 0 | L13: 984.85714 | M13: 1140 | N13: 54547 | O13: 10837 | P13: 0 | Q13: 910.32258 | R13: 1127.9032 | S13: 64673 | T13: 8299 | U13: 0 | V13: 921.33333 | W13: 1115.6667 | X13: 69295 | Y13: 5329 | Z13: 0 | AA13: 887.09677 | AB13: 1052.5806 | AC13: 64788 | AD13: 5407 | AE13: 0 | AF13: 897.16667 | AG13: 1050.5 | AH13: 57947 | AI13: 5160 | AJ13: 0 | AK13: 897.90323 | AL13: 1069.8387 | AM13: 64346 | AN13: 5390 | AO13: 0 | AP13: 883.3871 | AQ13: 1083.871 | AR13: 71399 | AS13: 5796 | AT13: 0 | AU13: 875.16667 | AV13: 1049.3333 | AW13: 81004 | AX13: 5179 | AY13: 0 | AZ13: 902.90323 | BA13: 1042.5806 | BB13: 51856 | BC13: 5099 | BD13: 0 | BE13: 910.83333 | BF13: 1021.3333 | BG13: 54346 | BH13: 4815 | BI13: 0 | BJ13: 900.93548 | BK13: 1008.3871
A14: 10 | B14: Warri | C14: Rainoil Agbarho - Ohrerhe | D14: 127647 | E14: 21072 | F14: 0 | G14: 1005.9677 | H14: 1150 | I14: 119217 | J14: 14092 | K14: 0 | L14: 992.32143 | M14: 1150 | N14: 137086 | O14: 16447 | P14: 0 | Q14: 936.29032 | R14: 1150 | S14: 171344 | T14: 15035 | U14: 0 | V14: 944.33333 | W14: 1135 | X14: 164773 | Y14: 15330 | Z14: 0 | AA14: 913.22581 | AB14: 1087.4194 | AC14: 169035 | AD14: 21294 | AE14: 0 | AF14: 924.83333 | AG14: 1079.3333 | AH14: 166764 | AI14: 24468 | AJ14: 0 | AK14: 920.64516 | AL14: 1090 | AM14: 169182 | AN14: 26790 | AO14: 0 | AP14: 910 | AQ14: 1109.3548 | AR14: 171304 | AS14: 21111 | AT14: 0 | AU14: 892 | AV14: 1100 | AW14: 172360 | AX14: 21932 | AY14: 0 | AZ14: 913.22581 | BA14: 1088.0645 | BB14: 191983 | BC14: 22958 | BD14: 0 | BE14: 918.33333 | BF14: 1063.3333 | BG14: 196315 | BH14: 27421 | BI14: 0 | BJ14: 895.32258 | BK14: 1044.8387
A15: 11 | B15: Warri | C15: Rainoil Agbarho - Ewherhe | D15: 194345 | E15: 15076 | F15: 0 | G15: 1006.7742 | H15: 1150 | I15: 165096 | J15: 14819 | K15: 0 | L15: 1000.1786 | M15: 1150 | N15: 200533 | O15: 13603 | P15: 0 | Q15: 941.45161 | R15: 1150 | S15: 216418 | T15: 11129 | U15: 0 | V15: 944.33333 | W15: 1135 | X15: 220698 | Y15: 11197 | Z15: 0 | AA15: 913.22581 | AB15: 1087.4194 | AC15: 210609 | AD15: 8009 | AE15: 0 | AF15: 924.83333 | AG15: 1079.3333 | AH15: 194115 | AI15: 7443 | AJ15: 0 | AK15: 920.64516 | AL15: 1090 | AM15: 193469 | AN15: 7262 | AO15: 0 | AP15: 910 | AQ15: 1109.3548 | AR15: 206741 | AS15: 4669 | AT15: 0 | AU15: 892 | AV15: 1100 | AW15: 203035 | AX15: 7464 | AY15: 0 | AZ15: 913.22581 | BA15: 1088.0645 | BB15: 212139 | BC15: 7011 | BD15: 0 | BE15: 919.33333 | BF15: 1063.3333 | BG15: 228412 | BH15: 11296 | BI15: 0 | BJ15: 895.32258 | BK15: 1044.8387
A16: 12 | B16: Agbor | C16: Rainoil Agbor - Asaba Road | D16: 236641 | E16: 49961 | F16: 750 | G16: 1018.0645 | H16: 1150 | I16: 265672 | J16: 57593 | K16: 721 | L16: 1001.4286 | M16: 1144.2857 | N16: 281376 | O16: 55982 | P16: 831 | Q16: 939.51613 | R16: 1130 | S16: 285435 | T16: 63321 | U16: 1580 | V16: 946.66667 | W16: 1112.8333 | X16: 282070 | Y16: 58492 | Z16: 1250 | AA16: 915.80645 | AB16: 1078.7097 | AC16: 248816 | AD16: 49434 | AE16: 1056 | AF16: 926.16667 | AG16: 1073 | AH16: 242347 | AI16: 46393 | AJ16: 1558 | AK16: 924.19355 | AL16: 1090 | AM16: 255542 | AN16: 46481 | AO16: 1206 | AP16: 910.32258 | AQ16: 1107.7419 | AR16: 247875 | AS16: 47227 | AT16: 1215 | AU16: 893 | AV16: 1100 | AW16: 292517 | AX16: 61062 | AY16: 1626 | AZ16: 915.16129 | BA16: 1087.0968 | BB16: 293866 | BC16: 60413 | BD16: 1618 | BE16: 920 | BF16: 1062.6667 | BG16: 317382 | BH16: 51147 | BI16: 1062 | BJ16: 900.64516 | BK16: 1039.0323
... A184: 180 | B184: FCT | C184: Rainoil Maraba | D184: 188703 | E184: 2112 | F184: 0 | G184: 993.33333 | H184: 1160 | I184: 229455 | J184: 4293 | K184: 0 | L184: 989.28571 | M184: 1166.0714 | N184: 198974 | O184: 4218 | P184: 0 | Q184: 945.80645 | R184: 1170 | S184: 252235 | T184: 2802 | U184: 0 | V184: 950.66667 | W184: 1159 | X184: 217657 | Y184: 2279 | Z184: 0 | AA184: 920 | AB184: 1133.871 | AC184: 194445 | AD184: 1375 | AE184: 0 | AF184: 920.66667 | AG184: 1130 | AH184: 179745 | AI184: 2583 | AJ184: 0 | AK184: 916.29032 | AL184: 1106.7742 | AM184: 194243 | AN184: 1792 | AO184: 0 | AP184: 913.06452 | AQ184: 1116.7742 | AR184: 189965 | AS184: 3021 | AT184: 0 | AU184: 894 | AV184: 1100 | AW184: 266082 | AX184: 2389 | AY184: 0 | AZ184: 933.54839 | BA184: 1087.4194 | BB184: 218620 | BC184: 2339 | BD184: 0 | BE184: 943 | BF184: 1047.3333 | BG184: 219950 | BH184: 3588 | BI184: 0 | BJ184: 912.41935 | BK184: 1040
A185: 181 | B185: Warri | C185: Rainoil Osubi - Airport Road | D185: 0 | E185: 0 | F185: 0 | I185: 74775 | J185: 7589 | K185: 0 | L185: 988.82353 | M185: 1150 | N185: 158478 | O185: 15618 | P185: 0 | Q185: 940.48387 | R185: 1150 | S185: 179258 | T185: 16317 | U185: 0 | V185: 944.33333 | W185: 1135 | X185: 180314 | Y185: 27326 | Z185: 0 | AA185: 913.22581 | AB185: 1087.4194 | AC185: 182510 | AD185: 35538 | AE185: 0 | AF185: 924.83333 | AG185: 1079.3333 | AH185: 191293 | AI185: 60675 | AJ185: 0 | AK185: 920.64516 | AL185: 1090 | AM185: 187786 | AN185: 62468 | AO185: 0 | AP185: 910 | AQ185: 1109.3548 | AR185: 185634 | AS185: 58592 | AT185: 0 | AU185: 892 | AV185: 1100 | AW185: 189086 | AX185: 54108 | AY185: 0 | AZ185: 913.22581 | BA185: 1088.3871 | BB185: 190736 | BC185: 46889 | BD185: 0 | BE185: 919.66667 | BF185: 1063.3333 | BG185: 211966 | BH185: 48019 | BI185: 0 | BJ185: 895.32258 | BK185: 1044.8387
A186: 182 | B186: Yenagoa | C186: Rainoil Yenagoa Kpansia | D186: 0 | E186: 0 | F186: 0 | I186: 233268 | J186: 13107 | K186: 0 | L186: 988.21429 | M186: 1160 | N186: 452303 | O186: 45396 | P186: 0 | Q186: 948.06452 | R186: 1146.9355 | S186: 420870 | T186: 57036 | U186: 0 | V186: 944.33333 | W186: 1121 | X186: 406399 | Y186: 61533 | Z186: 0 | AA186: 913.22581 | AB186: 1087.4194 | AC186: 350292 | AD186: 51256 | AE186: 0 | AF186: 925.16667 | AG186: 1080 | AH186: 338176 | AI186: 68469 | AJ186: 0 | AK186: 919.03226 | AL186: 1087.7419 | AM186: 297427 | AN186: 60363 | AO186: 0 | AP186: 910 | AQ186: 1110.6452 | AR186: 317747 | AS186: 46461 | AT186: 0 | AU186: 892.33333 | AV186: 1100 | AW186: 295190 | AX186: 43080 | AY186: 0 | AZ186: 914.67742 | BA186: 1086.129 | BB186: 309634 | BC186: 48029 | BD186: 0 | BE186: 918.66667 | BF186: 1063.3333 | BG186: 308206 | BH186: 55827 | BI186: 0 | BJ186: 895.16129 | BK186: 1044.8387
A187: 183 | B187: South-West 2 | C187: Rainoil Ogbomosho | D187: 0 | E187: 0 | F187: 0 | I187: 0 | J187: 0 | K187: 0 | N187: 41434 | O187: 2122 | P187: 0 | Q187: 887.5 | R187: 1120 | S187: 228539 | T187: 4537 | U187: 0 | V187: 899.73333 | W187: 1112 | X187: 211864 | Y187: 6632 | Z187: 0 | AA187: 881.70968 | AB187: 1046.129 | AC187: 213836 | AD187: 7537 | AE187: 0 | AF187: 891.83333 | AG187: 1047.3333 | AH187: 166740 | AI187: 6254 | AJ187: 0 | AK187: 896.6129 | AL187: 1067.4194 | AM187: 135360 | AN187: 4814 | AO187: 0 | AP187: 879.35484 | AQ187: 1077.4194 | AR187: 128537 | AS187: 6713 | AT187: 0 | AU187: 870.66667 | AV187: 1050 | AW187: 141420 | AX187: 5705 | AY187: 0 | AZ187: 902.90323 | BA187: 1042.5806 | BB187: 147032 | BC187: 5604 | BD187: 0 | BE187: 909.33333 | BF187: 1020.3333 | BG187: 121155 | BH187: 10452 | BI187: 0 | BJ187: 896.6129 | BK187: 1008.9677
A188: 184 | B188: Delta | C188: Rainoil Ugbolu | D188: 0 | E188: 0 | F188: 0 | I188: 0 | J188: 0 | K188: 0 | N188: 0 | O188: 0 | P188: 0 | S188: 117623 | T188: 5036 | U188: 0 | V188: 940.47619 | W188: 1105.7143 | X188: 187844 | Y188: 13204 | Z188: 0 | AA188: 915.80645 | AB188: 1078.7097 | AC188: 189843 | AD188: 11923 | AE188: 0 | AF188: 926.16667 | AG188: 1073 | AH188: 212379 | AI188: 15768 | AJ188: 0 | AK188: 925.48387 | AL188: 1090 | AM188: 211185 | AN188: 18879 | AO188: 0 | AP188: 915.48387 | AQ188: 1106.129 | AR188: 220380 | AS188: 22038 | AT188: 0 | AU188: 900.33333 | AV188: 1100 | AW188: 224153 | AX188: 18758 | AY188: 0 | AZ188: 916.45161 | BA188: 1094.1935 | BB188: 226068 | BC188: 12888 | BD188: 0 | BE188: 921.66667 | BF188: 1075.6667 | BG188: 242458 | BH188: 11772 | BI188: 0 | BJ188: 901.45161 | BK188: 1049.0323
A189: 185 | B189: North Central | C189: Rainoil North Bank | D189: 0 | E189: 0 | F189: 0 | I189: 0 | J189: 0 | K189: 0 | N189: 0 | O189: 0 | P189: 0 | S189: 5920 | T189: 741 | U189: 0 | V189: 930 | W189: 1140 | X189: 139343 | Y189: 4977 | Z189: 0 | AA189: 917.58065 | AB189: 1111.6129 | AC189: 145118 | AD189: 4915 | AE189: 0 | AF189: 921.5 | AG189: 1096.6667 | AH189: 140305 | AI189: 12680 | AJ189: 0 | AK189: 918.22581 | AL189: 1105.8065 | AM189: 138672 | AN189: 8631 | AO189: 0 | AP189: 919.51613 | AQ189: 1116.7742 | AR189: 120644 | AS189: 6161 | AT189: 0 | AU189: 893.5 | AV189: 1100 | AW189: 124937 | AX189: 5708 | AY189: 0 | AZ189: 935.16129 | BA189: 1097.0968 | BB189: 130060 | BC189: 8790 | BD189: 0 | BE189: 943.33333 | BF189: 1062 | BG189: 129423 | BH189: 8467 | BI189: 0 | BJ189: 905.16129 | BK189: 1060
A190: 186 | B190: Warri | C190: Rainoil Giwa-Amu | D190: 0 | E190: 0 | F190: 0 | I190: 0 | J190: 0 | K190: 0 | N190: 0 | O190: 0 | P190: 0 | S190: 0 | T190: 0 | U190: 0 | X190: 97905 | Y190: 1653 | Z190: 0 | AA190: 912.77778 | AB190: 1078.3333 | AC190: 180905 | AD190: 8320 | AE190: 0 | AF190: 924.83333 | AG190: 1079.3333 | AH190: 156084 | AI190: 14216 | AJ190: 0 | AK190: 920.64516 | AL190: 1090 | AM190: 146243 | AN190: 8411 | AO190: 0 | AP190: 910 | AQ190: 1109.3548 | AR190: 165634 | AS190: 7142 | AT190: 0 | AU190: 892 | AV190: 1100 | AW190: 174521 | AX190: 9624 | AY190: 0 | AZ190: 913.22581 | BA190: 1088.0645 | BB190: 192854 | BC190: 10916 | BD190: 0 | BE190: 919.33333 | BF190: 1063.3333 | BG190: 202375 | BH190: 10627 | BI190: 0 | BJ190: 895.32258 | BK190: 1044.8387
A191: 187 | B191: Calabar-PH | C191: Fynefield Abak Town | D191: 0 | E191: 0 | F191: 0 | I191: 0 | J191: 0 | K191: 0 | N191: 0 | O191: 0 | P191: 0 | S191: 0 | T191: 0 | U191: 0 | X191: 0 | Y191: 0 | Z191: 0 | AC191: 52830 | AD191: 2293 | AE191: 0 | AF191: 947.72727 | AG191: 1094.5455 | AH191: 149128 | AI191: 8906 | AJ191: 0 | AK191: 919.19355 | AL191: 1091.7742 | AM191: 173496 | AN191: 4949 | AO191: 0 | AP191: 910 | AQ191: 1093.2258 | AR191: 165296 | AS191: 11808 | AT191: 0 | AU191: 895.33333 | AV191: 1090 | AW191: 195338 | AX191: 11798 | AY191: 0 | AZ191: 907.41935 | BA191: 1087.4194 | BB191: 215667 | BC191: 12564 | BD191: 0 | BE191: 920 | BF191: 1074 | BG191: 243232 | BH191: 9354 | BI191: 0 | BJ191: 892.25806 | BK191: 1049.6774
A192: 188 | B192: Warri | C192: Rainoil Eboh Road | D192: 0 | E192: 0 | F192: 0 | I192: 0 | J192: 0 | K192: 0 | N192: 0 | O192: 0 | P192: 0 | S192: 0 | T192: 0 | U192: 0 | X192: 0 | Y192: 0 | Z192: 0 | AC192: 0 | AD192: 0 | AE192: 0 | AH192: 144677 | AI192: 3336 | AJ192: 0 | AK192: 920.64516 | AL192: 1090 | AM192: 170463 | AN192: 6089 | AO192: 0 | AP192: 910 | AQ192: 1109.3548 | AR192: 225689 | AS192: 9861 | AT192: 0 | AU192: 892 | AV192: 1100 | AW192: 225527 | AX192: 7184 | AY192: 0 | AZ192: 913.22581 | BA192: 1088.0645 | BB192: 243275 | BC192: 8350 | BD192: 0 | BE192: 919.33333 | BF192: 1063.3333 | BG192: 282541 | BH192: 10427 | BI192: 0 | BJ192: 895.32258 | BK192: 1044.8387
A193: 189 | B193: Ughelli | C193: Rainoil Patani | D193: 0 | E193: 0 | F193: 0 | I193: 0 | J193: 0 | K193: 0 | N193: 0 | O193: 0 | P193: 0 | S193: 0 | T193: 0 | U193: 0 | X193: 0 | Y193: 0 | Z193: 0 | AC193: 0 | AD193: 0 | AE193: 0 | AH193: 88216 | AI193: 13685 | AJ193: 0 | AK193: 912.72727 | AL193: 1085.2273 | AM193: 159129 | AN193: 18682 | AO193: 0 | AP193: 911.6129 | AQ193: 1109.1935 | AR193: 182370 | AS193: 25929 | AT193: 0 | AU193: 891 | AV193: 1100 | AW193: 186993 | AX193: 24853 | AY193: 0 | AZ193: 910.80645 | BA193: 1087.7419 | BB193: 207058 | BC193: 22459 | BD193: 0 | BE193: 919.33333 | BF193: 1063.3333 | BG193: 230049 | BH193: 19644 | BI193: 0 | BJ193: 895.32258 | BK193: 1044.8387
A194: 190 | B194: Ughelli | C194: Rainoil Ughelli Otovwodo | D194: 0 | E194: 0 | F194: 0 | I194: 0 | J194: 0 | K194: 0 | N194: 0 | O194: 0 | P194: 0 | S194: 0 | T194: 0 | U194: 0 | X194: 0 | Y194: 0 | Z194: 0 | AC194: 0 | AD194: 0 | AE194: 0 | AH194: 0 | AI194: 0 | AJ194: 0 | AM194: 0 | AN194: 0 | AO194: 0 | AR194: 352147 | AS194: 23946 | AT194: 0 | AU194: 881.78571 | AV194: 1090.7143 | AW194: 393098 | AX194: 23948 | AY194: 0 | AZ194: 910.48387 | BA194: 1085.1613 | BB194: 312207 | BC194: 21866 | BD194: 0 | BE194: 919.33333 | BF194: 1063.3333 | BG194: 195181 | BH194: 16556 | BI194: 0 | BJ194: 895.32258 | BK194: 1044.8387
A195: 191 | B195: South-East 2 | C195: Rainoil Aba - Faulks Road | D195: 0 | E195: 0 | F195: 0 | I195: 0 | J195: 0 | K195: 0 | N195: 0 | O195: 0 | P195: 0 | S195: 0 | T195: 0 | U195: 0 | X195: 0 | Y195: 0 | Z195: 0 | AC195: 0 | AD195: 0 | AE195: 0 | AH195: 0 | AI195: 0 | AJ195: 0 | AM195: 0 | AN195: 0 | AO195: 0 | AR195: 0 | AS195: 0 | AT195: 0 | AW195: 9259 | AX195: 383 | AY195: 0 | AZ195: 930 | BA195: 1080 | BB195: 97196 | BC195: 6900 | BD195: 0 | BE195: 930 | BF195: 1080 | BG195: 104746 | BH195: 12385 | BI195: 0 | BJ195: 896.45161 | BK195: 1066.129
A196: 192 | B196: Benin | C196: Rainoil Uselu Shell | D196: 0 | E196: 0 | F196: 0 | I196: 0 | J196: 0 | K196: 0 | N196: 0 | O196: 0 | P196: 0 | S196: 0 | T196: 0 | U196: 0 | X196: 0 | Y196: 0 | Z196: 0 | AC196: 0 | AD196: 0 | AE196: 0 | AH196: 0 | AI196: 0 | AJ196: 0 | AM196: 0 | AN196: 0 | AO196: 0 | AR196: 0 | AS196: 0 | AT196: 0 | AW196: 0 | AX196: 0 | AY196: 0 | BB196: 34435 | BC196: 760 | BD196: 0 | BE196: 915 | BF196: 1061.4286 | BG196: 44182 | BH196: 2075 | BI196: 0 | BJ196: 892.41935 | BK196: 1044.8387
A197: 193 | B197: Ughelli | C197: Rainoil Ughelli Post Office | D197: 0 | E197: 0 | F197: 0 | I197: 0 | J197: 0 | K197: 0 | N197: 0 | O197: 0 | P197: 0 | S197: 0 | T197: 0 | U197: 0 | X197: 0 | Y197: 0 | Z197: 0 | AC197: 0 | AD197: 0 | AE197: 0 | AH197: 0 | AI197: 0 | AJ197: 0 | AM197: 0 | AN197: 0 | AO197: 0 | AR197: 0 | AS197: 0 | AT197: 0 | AW197: 0 | AX197: 0 | AY197: 0 | BB197: 0 | BC197: 0 | BD197: 0 | BG197: 304915 | BH197: 17999 | BI197: 0 | BJ197: 894.83871 | BK197: 1044.8387
A305: 266
A306: 267
A307: 268
A308: 269
A309: 270
A310: 271
A311: 272
A312: 273
A313: 274
A314: 275
...

Sheet 2025 SUMMARY
A1: S/N | B1: MONTH | C1: PMS | D1: AGO | E1: DPK | F1: AVG PMS PRICE | G1: AVG AGO PRICE | H1: NO OF STATIONS
A2: 1 | B2: 45658 | C2: =SUM('2025 MOM Station Sale'!D5:D197) -> 37108262 | D2: =SUM('2025 MOM Station Sale'!E5:E197) -> 5257718 | E2: =SUM('2025 MOM Station Sale'!F5:F197) -> 62371 | F2: =AVERAGE('2025 MOM Station Sale'!G5:G197) -> 1018.0642 | G2: =AVERAGE('2025 MOM Station Sale'!H5:H197) -> 1162.7339 | H2: =COUNTA('2025 MOM Station Sale'!C5:C184) -> 180
A3: =A2+1 -> 2 | B3: 45689 | C3: =SUM('2025 MOM Station Sale'!I5:I197) -> 33137144 | D3: =SUM('2025 MOM Station Sale'!J5:J197) -> 5612014 | E3: =SUM('2025 MOM Station Sale'!K5:K197) -> 65708 | F3: =AVERAGE('2025 MOM Station Sale'!L5:L197) -> 1000.3577 | G3: =AVERAGE('2025 MOM Station Sale'!M5:M197) -> 1158.2996 | H3: =COUNTA('2025 MOM Station Sale'!I5:I186) -> 182
A4: =A3+1 -> 3 | B4: 45717 | C4: =SUM('2025 MOM Station Sale'!N5:N197) -> 36801732 | D4: =SUM('2025 MOM Station Sale'!O5:O197) -> 5872767 | E4: =SUM('2025 MOM Station Sale'!P5:P197) -> 81739 | F4: =AVERAGE('2025 MOM Station Sale'!Q5:Q197) -> 941.85167 | G4: =AVERAGE('2025 MOM Station Sale'!R5:R197) -> 1146.4428 | H4: =COUNTA('2025 MOM Station Sale'!N5:N187) -> 183
A5: =A4+1 -> 4 | B5: 45748 | C5: =SUM('2025 MOM Station Sale'!S5:S197) -> 37843329 | D5: =SUM('2025 MOM Station Sale'!T5:T197) -> 5931156 | E5: =SUM('2025 MOM Station Sale'!U5:U197) -> 83785 | F5: =AVERAGE('2025 MOM Station Sale'!V5:V197) -> 946.04708 | G5: =AVERAGE('2025 MOM Station Sale'!W5:W197) -> 1131.8714 | H5: =COUNTA('2025 MOM Station Sale'!S5:S189) -> 185
A6: =A5+1 -> 5 | B6: 45778 | C6: =SUM('2025 MOM Station Sale'!X5:X197) -> 37006730 | D6: =SUM('2025 MOM Station Sale'!Y5:Y197) -> 5617995 | E6: =SUM('2025 MOM Station Sale'!Z5:Z197) -> 93147 | F6: =AVERAGE('2025 MOM Station Sale'!AA5:AA197) -> 913.47765 | G6: =AVERAGE('2025 MOM Station Sale'!AB5:AB197) -> 1093.583 | H6: =COUNTA('2025 MOM Station Sale'!X5:X190) -> 186
A7: =A6+1 -> 6 | B7: 45809 | C7: =SUM('2025 MOM Station Sale'!AC5:AC197) -> 34059763 | D7: =SUM('2025 MOM Station Sale'!AD5:AD197) -> 5079858 | E7: =SUM('2025 MOM Station Sale'!AE5:AE197) -> 100406 | F7: =AVERAGE('2025 MOM Station Sale'!AF5:AF197) -> 921.62831 | G7: =AVERAGE('2025 MOM Station Sale'!AG5:AG197) -> 1083.35 | H7: =COUNTA('2025 MOM Station Sale'!AC5:AC191) -> 187
A8: =A7+1 -> 7 | B8: 45839 | C8: =SUM('2025 MOM Station Sale'!AH5:AH197) -> 33087343 | D8: =SUM('2025 MOM Station Sale'!AI5:AI197) -> 5332915.8 | E8: =SUM('2025 MOM Station Sale'!AJ5:AJ197) -> 97633 | F8: =AVERAGE('2025 MOM Station Sale'!AK5:AK197) -> 919.65106 | G8: =AVERAGE('2025 MOM Station Sale'!AL5:AL197) -> 1093.0826 | H8: =COUNTA('2025 MOM Station Sale'!AH5:AH193) -> 189
A9: =A8+1 -> 8 | B9: 45870 | C9: =SUM('2025 MOM Station Sale'!AM5:AM197) -> 33692612 | D9: =SUM('2025 MOM Station Sale'!AN5:AN197) -> 5201862 | E9: =SUM('2025 MOM Station Sale'!AO5:AO197) -> 84028 | F9: =AVERAGE('2025 MOM Station Sale'!AP5:AP197) -> 910.66383 | G9: =AVERAGE('2025 MOM Station Sale'!AQ5:AQ197) -> 1106.3799 | H9: =COUNTA('2025 MOM Station Sale'!AM5:AM193) -> 189
A10: =A9+1 -> 9 | B10: 45901 | C10: =SUM('2025 MOM Station Sale'!AR5:AR197) -> 35030017 | D10: =SUM('2025 MOM Station Sale'!AS5:AS197) -> 5115756 | E10: =SUM('2025 MOM Station Sale'!AT5:AT197) -> 77762 | F10: =AVERAGE('2025 MOM Station Sale'!AU5:AU197) -> 892.38554 | G10: =AVERAGE('2025 MOM Station Sale'!AV5:AV197) -> 1093.588 | H10: =COUNTA('2025 MOM Station Sale'!AR5:AR194) -> 190
A11: =A10+1 -> 10 | B11: 45931 | C11: =SUM('2025 MOM Station Sale'!AW5:AW197) -> 38103201 | D11: =SUM('2025 MOM Station Sale'!AX5:AX197) -> 5196501 | E11: =SUM('2025 MOM Station Sale'!AY5:AY197) -> 54924 | F11: =AVERAGE('2025 MOM Station Sale'!AZ5:AZ197) -> 915.81803 | G11: =AVERAGE('2025 MOM Station Sale'!BA5:BA197) -> 1082.5297 | H11: =COUNTA('2025 MOM Station Sale'!AW5:AW195) -> 191
A12: =A11+1 -> 11 | B12: 45962 | C12: =SUM('2025 MOM Station Sale'!BB5:BB197) -> 36171277 | D12: =SUM('2025 MOM Station Sale'!BC5:BC197) -> 5604075 | E12: =SUM('2025 MOM Station Sale'!BD5:BD197) -> 44979 | F12: =AVERAGE('2025 MOM Station Sale'!BE5:BE197) -> 920.9783 | G12: =AVERAGE('2025 MOM Station Sale'!BF5:BF197) -> 1056.7366 | H12: =COUNTA('2025 MOM Station Sale'!BB5:BB196) -> 192
A13: =A12+1 -> 12 | B13: 45992 | C13: =SUM('2025 MOM Station Sale'!BG5:BG197) -> 40145368 | D13: =SUM('2025 MOM Station Sale'!BH5:BH197) -> 6029383 | E13: =SUM('2025 MOM Station Sale'!BI5:BI197) -> 41821 | F13: =AVERAGE('2025 MOM Station Sale'!BJ5:BJ197) -> 895.55704 | G13: =AVERAGE('2025 MOM Station Sale'!BK5:BK197) -> 1039.7335 | H13: =COUNTA('2025 MOM Station Sale'!BG5:BG197) -> 193

Sheet Sheet2
